from logging import exception
from db import get_connection


def create_table():
    conn = get_connection()
    if conn is None:
        return
    cursor = conn.cursor()

    try:
        cursor.execute(
            "CREATE TABLE USERS(id_users serial PRIMARY KEY,name varchar(50),email varchar(150) UNIQUE,password varchar(255));"
        )

        conn.commit()
        cursor.close()
        conn.close()
        return True
    except Exception as e:
        if 'relation "users" already exists' in str(e):
            return True
        else:
            return e


def list_users():
    conn = get_connection()
    if conn is None:
        return
    try:
        cursor = conn.cursor()
        cursor.execute("SELECT name,id_users FROM users;")
        users = cursor.fetchall()

        cursor.close()
        conn.close()

        return users
    except Exception as e:
        print("Erro ao retornar usu√°rios", e)
        return []

def insert_user(name, email, password):
    conn = get_connection()

    if conn is None:
        return
    
    try: 
        cursor = conn.cursor()
        cursor.execute("INSERT INTO USERS(name, email, password) VALUES (%s, %s,%s)", (name, email, password))
        conn.commit()
        cursor.close()
        conn.close()
        return True
    except Exception as e:
        print(e)
        return False
